INFO:2024-06-19 18:40:37,877 run_model - SCRIPT STARTED
CRITICAL:2024-06-19 18:40:38,334 run_model - HTTPSConnectionPool(host='moggglga.softaria.com', port=443): Max retries exceeded with url: /api/learning/ml/course (Caused by SSLError(SSLCertVerificationError(1, "[SSL: CERTIFICATE_VERIFY_FAILED] certificate verify failed: Hostname mismatch, certificate is not valid for 'moggglga.softaria.com'. (_ssl.c:1000)")))
Traceback (most recent call last):
  File "/Library/Frameworks/Python.framework/Versions/3.12/lib/python3.12/site-packages/urllib3/connectionpool.py", line 467, in _make_request
    self._validate_conn(conn)
  File "/Library/Frameworks/Python.framework/Versions/3.12/lib/python3.12/site-packages/urllib3/connectionpool.py", line 1096, in _validate_conn
    conn.connect()
  File "/Library/Frameworks/Python.framework/Versions/3.12/lib/python3.12/site-packages/urllib3/connection.py", line 642, in connect
    sock_and_verified = _ssl_wrap_socket_and_match_hostname(
                        ^^^^^^^^^^^^^^^^^^^^^^^^^^^^^^^^^^^^
  File "/Library/Frameworks/Python.framework/Versions/3.12/lib/python3.12/site-packages/urllib3/connection.py", line 782, in _ssl_wrap_socket_and_match_hostname
    ssl_sock = ssl_wrap_socket(
               ^^^^^^^^^^^^^^^^
  File "/Library/Frameworks/Python.framework/Versions/3.12/lib/python3.12/site-packages/urllib3/util/ssl_.py", line 470, in ssl_wrap_socket
    ssl_sock = _ssl_wrap_socket_impl(sock, context, tls_in_tls, server_hostname)
               ^^^^^^^^^^^^^^^^^^^^^^^^^^^^^^^^^^^^^^^^^^^^^^^^^^^^^^^^^^^^^^^^^
  File "/Library/Frameworks/Python.framework/Versions/3.12/lib/python3.12/site-packages/urllib3/util/ssl_.py", line 514, in _ssl_wrap_socket_impl
    return ssl_context.wrap_socket(sock, server_hostname=server_hostname)
           ^^^^^^^^^^^^^^^^^^^^^^^^^^^^^^^^^^^^^^^^^^^^^^^^^^^^^^^^^^^^^^
  File "/Library/Frameworks/Python.framework/Versions/3.12/lib/python3.12/ssl.py", line 455, in wrap_socket
    return self.sslsocket_class._create(
           ^^^^^^^^^^^^^^^^^^^^^^^^^^^^^
  File "/Library/Frameworks/Python.framework/Versions/3.12/lib/python3.12/ssl.py", line 1046, in _create
    self.do_handshake()
  File "/Library/Frameworks/Python.framework/Versions/3.12/lib/python3.12/ssl.py", line 1321, in do_handshake
    self._sslobj.do_handshake()
ssl.SSLCertVerificationError: [SSL: CERTIFICATE_VERIFY_FAILED] certificate verify failed: Hostname mismatch, certificate is not valid for 'moggglga.softaria.com'. (_ssl.c:1000)

During handling of the above exception, another exception occurred:

Traceback (most recent call last):
  File "/Library/Frameworks/Python.framework/Versions/3.12/lib/python3.12/site-packages/urllib3/connectionpool.py", line 790, in urlopen
    response = self._make_request(
               ^^^^^^^^^^^^^^^^^^^
  File "/Library/Frameworks/Python.framework/Versions/3.12/lib/python3.12/site-packages/urllib3/connectionpool.py", line 491, in _make_request
    raise new_e
urllib3.exceptions.SSLError: [SSL: CERTIFICATE_VERIFY_FAILED] certificate verify failed: Hostname mismatch, certificate is not valid for 'moggglga.softaria.com'. (_ssl.c:1000)

The above exception was the direct cause of the following exception:

Traceback (most recent call last):
  File "/Library/Frameworks/Python.framework/Versions/3.12/lib/python3.12/site-packages/requests/adapters.py", line 486, in send
    resp = conn.urlopen(
           ^^^^^^^^^^^^^
  File "/Library/Frameworks/Python.framework/Versions/3.12/lib/python3.12/site-packages/urllib3/connectionpool.py", line 844, in urlopen
    retries = retries.increment(
              ^^^^^^^^^^^^^^^^^^
  File "/Library/Frameworks/Python.framework/Versions/3.12/lib/python3.12/site-packages/urllib3/util/retry.py", line 515, in increment
    raise MaxRetryError(_pool, url, reason) from reason  # type: ignore[arg-type]
    ^^^^^^^^^^^^^^^^^^^^^^^^^^^^^^^^^^^^^^^^^^^^^^^^^^^
urllib3.exceptions.MaxRetryError: HTTPSConnectionPool(host='moggglga.softaria.com', port=443): Max retries exceeded with url: /api/learning/ml/course (Caused by SSLError(SSLCertVerificationError(1, "[SSL: CERTIFICATE_VERIFY_FAILED] certificate verify failed: Hostname mismatch, certificate is not valid for 'moggglga.softaria.com'. (_ssl.c:1000)")))

During handling of the above exception, another exception occurred:

Traceback (most recent call last):
  File "/Users/gavril/Downloads/recomedation_hr/test.py", line 34, in run_model
    download_data()
  File "/Users/gavril/Downloads/recomedation_hr/test.py", line 16, in download_data
    r= requests.get('https://moggglga.softaria.com/api/learning/ml/course')
       ^^^^^^^^^^^^^^^^^^^^^^^^^^^^^^^^^^^^^^^^^^^^^^^^^^^^^^^^^^^^^^^^^^^^
  File "/Library/Frameworks/Python.framework/Versions/3.12/lib/python3.12/site-packages/requests/api.py", line 73, in get
    return request("get", url, params=params, **kwargs)
           ^^^^^^^^^^^^^^^^^^^^^^^^^^^^^^^^^^^^^^^^^^^^
  File "/Library/Frameworks/Python.framework/Versions/3.12/lib/python3.12/site-packages/requests/api.py", line 59, in request
    return session.request(method=method, url=url, **kwargs)
           ^^^^^^^^^^^^^^^^^^^^^^^^^^^^^^^^^^^^^^^^^^^^^^^^^
  File "/Library/Frameworks/Python.framework/Versions/3.12/lib/python3.12/site-packages/requests/sessions.py", line 589, in request
    resp = self.send(prep, **send_kwargs)
           ^^^^^^^^^^^^^^^^^^^^^^^^^^^^^^
  File "/Library/Frameworks/Python.framework/Versions/3.12/lib/python3.12/site-packages/requests/sessions.py", line 703, in send
    r = adapter.send(request, **kwargs)
        ^^^^^^^^^^^^^^^^^^^^^^^^^^^^^^^
  File "/Library/Frameworks/Python.framework/Versions/3.12/lib/python3.12/site-packages/requests/adapters.py", line 517, in send
    raise SSLError(e, request=request)
requests.exceptions.SSLError: HTTPSConnectionPool(host='moggglga.softaria.com', port=443): Max retries exceeded with url: /api/learning/ml/course (Caused by SSLError(SSLCertVerificationError(1, "[SSL: CERTIFICATE_VERIFY_FAILED] certificate verify failed: Hostname mismatch, certificate is not valid for 'moggglga.softaria.com'. (_ssl.c:1000)")))
INFO:2024-06-19 18:41:19,990 run_model - SCRIPT STARTED
WARNING:2024-06-19 18:41:20,509 download_data - Загружаю данные о крусах
WARNING:2024-06-19 18:41:20,515 download_data - ===> Данных о курсах успешно загружены
INFO:2024-06-19 22:11:13,570 run_model - SCRIPT STARTED
WARNING:2024-06-19 22:11:14,274 download_data - Загружаю данные о крусах
WARNING:2024-06-19 22:11:14,275 download_data - ===> Данных о курсах успешно загружены
INFO:2024-06-19 22:11:14,575 post_data - ===> Данных о рекомендация загружены на портал
INFO:2024-06-19 22:11:14,578 run_model - SCRIPT FINISHED SUCCESSFULLY
INFO:2024-06-19 22:11:16,141 run_model - SCRIPT STARTED
WARNING:2024-06-19 22:11:16,648 download_data - Загружаю данные о крусах
WARNING:2024-06-19 22:11:16,649 download_data - ===> Данных о курсах успешно загружены
INFO:2024-06-19 22:11:16,879 post_data - ===> Данных о рекомендация загружены на портал
INFO:2024-06-19 22:11:16,881 run_model - SCRIPT FINISHED SUCCESSFULLY
INFO:2024-06-19 22:11:41,004 run_model - SCRIPT STARTED
WARNING:2024-06-19 22:11:41,429 download_data - Загружаю данные о крусах
WARNING:2024-06-19 22:11:41,429 download_data - ===> Данных о курсах успешно загружены
INFO:2024-06-19 22:11:41,703 post_data - ===> Данных о рекомендация загружены на портал
INFO:2024-06-19 22:11:41,711 run_model - SCRIPT FINISHED SUCCESSFULLY
INFO:2024-06-19 22:19:45,964 run_model - SCRIPT STARTED
WARNING:2024-06-19 22:19:46,500 download_data - Загружаю данные о крусах
WARNING:2024-06-19 22:19:46,501 download_data - ===> Данных о курсах успешно загружены
CRITICAL:2024-06-19 22:19:46,757 run_model - string indices must be integers, not 'str'
Traceback (most recent call last):
  File "/Users/gavril/Downloads/recomedation_hr/test.py", line 52, in run_model
    post_data(data)
  File "/Users/gavril/Downloads/recomedation_hr/test.py", line 37, in post_data
    logger.warning("===> не удалось загрузить",r.text["message"])
                                               ~~~~~~^^^^^^^^^^^
TypeError: string indices must be integers, not 'str'
INFO:2024-06-19 22:20:11,508 run_model - SCRIPT STARTED
WARNING:2024-06-19 22:20:12,054 download_data - Загружаю данные о крусах
WARNING:2024-06-19 22:20:12,054 download_data - ===> Данных о курсах успешно загружены
CRITICAL:2024-06-19 22:20:12,347 run_model - string indices must be integers, not 'str'
Traceback (most recent call last):
  File "/Users/gavril/Downloads/recomedation_hr/test.py", line 52, in run_model
    post_data(data)
  File "/Users/gavril/Downloads/recomedation_hr/test.py", line 37, in post_data
    logger.warning("===> не удалось загрузить",r.text["message"])
                                               ~~~~~~^^^^^^^^^^^
TypeError: string indices must be integers, not 'str'
INFO:2024-06-19 22:20:18,613 run_model - SCRIPT STARTED
WARNING:2024-06-19 22:20:18,968 download_data - Загружаю данные о крусах
WARNING:2024-06-19 22:20:18,968 download_data - ===> Данных о курсах успешно загружены
CRITICAL:2024-06-19 22:20:19,246 run_model - string indices must be integers, not 'str'
Traceback (most recent call last):
  File "/Users/gavril/Downloads/recomedation_hr/test.py", line 52, in run_model
    post_data(data)
  File "/Users/gavril/Downloads/recomedation_hr/test.py", line 37, in post_data
    logger.warning("===> не удалось загрузить",r.text["message"])
                                               ~~~~~~^^^^^^^^^^^
TypeError: string indices must be integers, not 'str'
INFO:2024-06-19 22:20:59,052 run_model - SCRIPT STARTED
WARNING:2024-06-19 22:20:59,569 download_data - Загружаю данные о крусах
WARNING:2024-06-19 22:20:59,569 download_data - ===> Данных о курсах успешно загружены
CRITICAL:2024-06-19 22:20:59,777 run_model - string indices must be integers, not 'str'
Traceback (most recent call last):
  File "/Users/gavril/Downloads/recomedation_hr/test.py", line 53, in run_model
    post_data(data)
  File "/Users/gavril/Downloads/recomedation_hr/test.py", line 38, in post_data
    logger.warning("===> не удалось загрузить",r.text["message"])
                                               ~~~~~~^^^^^^^^^^^
TypeError: string indices must be integers, not 'str'
INFO:2024-06-19 22:21:24,636 run_model - SCRIPT STARTED
WARNING:2024-06-19 22:21:24,989 download_data - Загружаю данные о крусах
WARNING:2024-06-19 22:21:24,990 download_data - ===> Данных о курсах успешно загружены
CRITICAL:2024-06-19 22:21:25,256 run_model - string indices must be integers, not 'str'
Traceback (most recent call last):
  File "/Users/gavril/Downloads/recomedation_hr/test.py", line 54, in run_model
    post_data(data)
  File "/Users/gavril/Downloads/recomedation_hr/test.py", line 39, in post_data
    logger.warning("===> не удалось загрузить",r.text["message"])
                                               ~~~~~~^^^^^^^^^^^
TypeError: string indices must be integers, not 'str'
INFO:2024-06-19 22:22:33,994 run_model - SCRIPT STARTED
INFO:2024-06-19 22:22:34,359 run_model - SCRIPT FINISHED SUCCESSFULLY
INFO:2024-06-19 22:22:54,065 run_model - SCRIPT STARTED
INFO:2024-06-19 22:22:54,438 run_model - SCRIPT FINISHED SUCCESSFULLY
INFO:2024-06-19 22:23:28,882 run_model - SCRIPT STARTED
INFO:2024-06-19 22:23:29,150 run_model - SCRIPT FINISHED SUCCESSFULLY
INFO:2024-06-19 22:24:02,430 run_model - SCRIPT STARTED
WARNING:2024-06-19 22:24:02,751 post_data - ===> не удалось загрузить
INFO:2024-06-19 22:24:43,726 run_model - SCRIPT STARTED
CRITICAL:2024-06-19 22:24:43,990 run_model - string indices must be integers, not 'str'
Traceback (most recent call last):
  File "/Users/gavril/Downloads/recomedation_hr/test.py", line 55, in run_model
    post_data(data)
  File "/Users/gavril/Downloads/recomedation_hr/test.py", line 40, in post_data
    logger.warning("===> не удалось загрузить",r.text["message"])
                                               ~~~~~~^^^^^^^^^^^
TypeError: string indices must be integers, not 'str'
INFO:2024-06-19 22:25:11,858 run_model - SCRIPT STARTED
WARNING:2024-06-19 22:25:12,197 post_data - ===> не удалось загрузить
INFO:2024-06-19 22:26:52,926 run_model - SCRIPT STARTED
WARNING:2024-06-19 22:26:53,277 post_data - {"timestamp":"2024-06-19T19:26:52.498+00:00","status":500,"error":"Internal Server Error","message":"could not execute statement [ERROR: duplicate key value violates unique constraint \"learning_ml_guidance_learning_guidance_learning_subject_are_key\"\n  Detail: Key (learning_guidance, learning_subject_area, learning_level)=(career, hr, 1) already exists.] [insert into learning_ml_guidance (learning_courses,learning_guidance,learning_level,learning_subject_area) values (?,?,?,?)]; SQL [insert into learning_ml_guidance (learning_courses,learning_guidance,learning_level,learning_subject_area) values (?,?,?,?)]; constraint [learning_ml_guidance_learning_guidance_learning_subject_are_key]","path":"/learning/ml/guidance"}
WARNING:2024-06-19 22:26:53,277 post_data - ===> не удалось загрузить
INFO:2024-06-19 22:27:41,326 run_model - SCRIPT STARTED
CRITICAL:2024-06-19 22:27:41,710 run_model - string indices must be integers, not 'str'
Traceback (most recent call last):
  File "/Users/gavril/Downloads/recomedation_hr/test.py", line 55, in run_model
    post_data(data)
  File "/Users/gavril/Downloads/recomedation_hr/test.py", line 40, in post_data
    logger.warning(r.text["message"])
                   ~~~~~~^^^^^^^^^^^
TypeError: string indices must be integers, not 'str'
INFO:2024-06-19 22:28:03,592 run_model - SCRIPT STARTED
CRITICAL:2024-06-19 22:28:03,953 run_model - 'str' object has no attribute 'message'
Traceback (most recent call last):
  File "/Users/gavril/Downloads/recomedation_hr/test.py", line 55, in run_model
    post_data(data)
  File "/Users/gavril/Downloads/recomedation_hr/test.py", line 40, in post_data
    logger.warning(r.text.message)
                   ^^^^^^^^^^^^^^
AttributeError: 'str' object has no attribute 'message'
INFO:2024-06-19 22:28:56,746 run_model - SCRIPT STARTED
CRITICAL:2024-06-19 22:28:57,023 run_model - 'str' object has no attribute 'json'
Traceback (most recent call last):
  File "/Users/gavril/Downloads/recomedation_hr/test.py", line 55, in run_model
    post_data(data)
  File "/Users/gavril/Downloads/recomedation_hr/test.py", line 40, in post_data
    logger.warning(r.text.json())
                   ^^^^^^^^^^^
AttributeError: 'str' object has no attribute 'json'
INFO:2024-06-19 22:30:08,074 run_model - SCRIPT STARTED
WARNING:2024-06-19 22:30:08,475 post_data - "{\"timestamp\":\"2024-06-19T19:30:07.701+00:00\",\"status\":500,\"error\":\"Internal Server Error\",\"message\":\"could not execute statement [ERROR: duplicate key value violates unique constraint \\\"learning_ml_guidance_learning_guidance_learning_subject_are_key\\\"\\n  Detail: Key (learning_guidance, learning_subject_area, learning_level)=(career, hr, 1) already exists.] [insert into learning_ml_guidance (learning_courses,learning_guidance,learning_level,learning_subject_area) values (?,?,?,?)]; SQL [insert into learning_ml_guidance (learning_courses,learning_guidance,learning_level,learning_subject_area) values (?,?,?,?)]; constraint [learning_ml_guidance_learning_guidance_learning_subject_are_key]\",\"path\":\"/learning/ml/guidance\"}"
WARNING:2024-06-19 22:30:08,476 post_data - ===> не удалось загрузить
INFO:2024-06-19 22:30:59,563 run_model - SCRIPT STARTED
CRITICAL:2024-06-19 22:30:59,900 run_model - string indices must be integers, not 'str'
Traceback (most recent call last):
  File "/Users/gavril/Downloads/recomedation_hr/test.py", line 55, in run_model
    post_data(data)
  File "/Users/gavril/Downloads/recomedation_hr/test.py", line 40, in post_data
    logger.warning(json.dumps(r.text)["message"])
                   ~~~~~~~~~~~~~~~~~~^^^^^^^^^^^
TypeError: string indices must be integers, not 'str'
INFO:2024-06-19 22:32:46,015 run_model - SCRIPT STARTED
CRITICAL:2024-06-19 22:32:46,288 run_model - string indices must be integers, not 'str'
Traceback (most recent call last):
  File "/Users/gavril/Downloads/recomedation_hr/test.py", line 56, in run_model
    post_data(data)
  File "/Users/gavril/Downloads/recomedation_hr/test.py", line 41, in post_data
    logger.warning(json.dumps(r.text)["message"])
                   ~~~~~~~~~~~~~~~~~~^^^^^^^^^^^
TypeError: string indices must be integers, not 'str'
INFO:2024-06-19 22:34:21,011 run_model - SCRIPT STARTED
CRITICAL:2024-06-19 22:34:21,380 run_model - string indices must be integers, not 'str'
Traceback (most recent call last):
  File "/Users/gavril/Downloads/recomedation_hr/test.py", line 57, in run_model
    post_data(data)
  File "/Users/gavril/Downloads/recomedation_hr/test.py", line 42, in post_data
    logger.warning(json.dumps(r.text)["message"])
                   ~~~~~~~~~~~~~~~~~~^^^^^^^^^^^
TypeError: string indices must be integers, not 'str'
INFO:2024-06-19 22:34:39,721 run_model - SCRIPT STARTED
CRITICAL:2024-06-19 22:34:40,044 run_model - string indices must be integers, not 'str'
Traceback (most recent call last):
  File "/Users/gavril/Downloads/recomedation_hr/test.py", line 57, in run_model
    post_data(data)
  File "/Users/gavril/Downloads/recomedation_hr/test.py", line 42, in post_data
    logger.warning(json.dumps(r.text)["message"])
                   ~~~~~~~~~~~~~~~~~~^^^^^^^^^^^
TypeError: string indices must be integers, not 'str'
INFO:2024-06-19 22:35:33,688 run_model - SCRIPT STARTED
CRITICAL:2024-06-19 22:35:33,958 run_model - string indices must be integers, not 'str'
Traceback (most recent call last):
  File "/Users/gavril/Downloads/recomedation_hr/test.py", line 57, in run_model
    post_data(data)
  File "/Users/gavril/Downloads/recomedation_hr/test.py", line 42, in post_data
    logger.warning(json.dumps(r.text)["message"])
                   ~~~~~~~~~~~~~~~~~~^^^^^^^^^^^
TypeError: string indices must be integers, not 'str'
INFO:2024-06-19 22:35:54,747 run_model - SCRIPT STARTED
CRITICAL:2024-06-19 22:35:55,074 run_model - string indices must be integers, not 'str'
Traceback (most recent call last):
  File "/Users/gavril/Downloads/recomedation_hr/test.py", line 57, in run_model
    post_data(data)
  File "/Users/gavril/Downloads/recomedation_hr/test.py", line 42, in post_data
    logger.warning(json.dumps(r.text)["message"])
                   ~~~~~~~~~~~~~~~~~~^^^^^^^^^^^
TypeError: string indices must be integers, not 'str'
INFO:2024-06-19 22:36:52,212 run_model - SCRIPT STARTED
CRITICAL:2024-06-19 22:36:52,449 run_model - string indices must be integers, not 'str'
Traceback (most recent call last):
  File "/Users/gavril/Downloads/recomedation_hr/test.py", line 57, in run_model
    post_data(data)
  File "/Users/gavril/Downloads/recomedation_hr/test.py", line 42, in post_data
    logger.warning(json.dumps(r.text)["message"])
                   ~~~~~~~~~~~~~~~~~~^^^^^^^^^^^
TypeError: string indices must be integers, not 'str'
INFO:2024-06-19 22:37:14,127 run_model - SCRIPT STARTED
INFO:2024-06-19 22:37:38,931 run_model - SCRIPT STARTED
INFO:2024-06-19 22:38:24,335 run_model - SCRIPT STARTED
WARNING:2024-06-19 22:38:24,712 post_data - could not execute statement [ERROR: duplicate key value violates unique constraint "learning_ml_guidance_learning_guidance_learning_subject_are_key"
  Detail: Key (learning_guidance, learning_subject_area, learning_level)=(career, hr, 1) already exists.] [insert into learning_ml_guidance (learning_courses,learning_guidance,learning_level,learning_subject_area) values (?,?,?,?)]; SQL [insert into learning_ml_guidance (learning_courses,learning_guidance,learning_level,learning_subject_area) values (?,?,?,?)]; constraint [learning_ml_guidance_learning_guidance_learning_subject_are_key]
INFO:2024-06-19 22:48:26,412 run_model - SCRIPT STARTED
INFO:2024-06-19 22:48:26,731 post_data - Hello could not execute statement [ERROR: duplicate key value violates unique constraint "learning_ml_guidance_learning_guidance_learning_subject_are_key"
  Detail: Key (learning_guidance, learning_subject_area, learning_level)=(career, hr, 1) already exists.] [insert into learning_ml_guidance (learning_courses,learning_guidance,learning_level,learning_subject_area) values (?,?,?,?)]; SQL [insert into learning_ml_guidance (learning_courses,learning_guidance,learning_level,learning_subject_area) values (?,?,?,?)]; constraint [learning_ml_guidance_learning_guidance_learning_subject_are_key]
INFO:2024-06-19 22:49:48,410 run_model - SCRIPT STARTED
INFO:2024-06-19 22:49:48,726 post_data - ===> не удалось загрузить рекомендации на портал:/n could not execute statement [ERROR: duplicate key value violates unique constraint "learning_ml_guidance_learning_guidance_learning_subject_are_key"
  Detail: Key (learning_guidance, learning_subject_area, learning_level)=(career, hr, 1) already exists.] [insert into learning_ml_guidance (learning_courses,learning_guidance,learning_level,learning_subject_area) values (?,?,?,?)]; SQL [insert into learning_ml_guidance (learning_courses,learning_guidance,learning_level,learning_subject_area) values (?,?,?,?)]; constraint [learning_ml_guidance_learning_guidance_learning_subject_are_key]
INFO:2024-06-19 22:53:16,351 run_model - SCRIPT STARTED
INFO:2024-06-19 22:53:16,708 post_data - ===> не удалось загрузить рекомендации на портал: /n could not execute statement [ERROR: duplicate key value violates unique constraint "learning_ml_guidance_learning_guidance_learning_subject_are_key"
  Detail: Key (learning_guidance, learning_subject_area, learning_level)=(career, hr, 1) already exists.] [insert into learning_ml_guidance (learning_courses,learning_guidance,learning_level,learning_subject_area) values (?,?,?,?)]; SQL [insert into learning_ml_guidance (learning_courses,learning_guidance,learning_level,learning_subject_area) values (?,?,?,?)]; constraint [learning_ml_guidance_learning_guidance_learning_subject_are_key]
INFO:2024-06-19 22:53:30,320 run_model - SCRIPT STARTED
INFO:2024-06-19 22:53:30,595 post_data - ===> не удалось загрузить рекомендации на портал: //n could not execute statement [ERROR: duplicate key value violates unique constraint "learning_ml_guidance_learning_guidance_learning_subject_are_key"
  Detail: Key (learning_guidance, learning_subject_area, learning_level)=(career, hr, 1) already exists.] [insert into learning_ml_guidance (learning_courses,learning_guidance,learning_level,learning_subject_area) values (?,?,?,?)]; SQL [insert into learning_ml_guidance (learning_courses,learning_guidance,learning_level,learning_subject_area) values (?,?,?,?)]; constraint [learning_ml_guidance_learning_guidance_learning_subject_are_key]
INFO:2024-06-19 22:54:24,712 run_model - SCRIPT STARTED
INFO:2024-06-19 22:54:25,091 post_data - ===> не удалось загрузить рекомендации на портал: 
 could not execute statement [ERROR: duplicate key value violates unique constraint "learning_ml_guidance_learning_guidance_learning_subject_are_key"
  Detail: Key (learning_guidance, learning_subject_area, learning_level)=(career, hr, 1) already exists.] [insert into learning_ml_guidance (learning_courses,learning_guidance,learning_level,learning_subject_area) values (?,?,?,?)]; SQL [insert into learning_ml_guidance (learning_courses,learning_guidance,learning_level,learning_subject_area) values (?,?,?,?)]; constraint [learning_ml_guidance_learning_guidance_learning_subject_are_key]
INFO:2024-06-19 22:54:26,300 run_model - SCRIPT STARTED
INFO:2024-06-19 22:54:26,632 post_data - ===> не удалось загрузить рекомендации на портал: 
 could not execute statement [ERROR: duplicate key value violates unique constraint "learning_ml_guidance_learning_guidance_learning_subject_are_key"
  Detail: Key (learning_guidance, learning_subject_area, learning_level)=(career, hr, 1) already exists.] [insert into learning_ml_guidance (learning_courses,learning_guidance,learning_level,learning_subject_area) values (?,?,?,?)]; SQL [insert into learning_ml_guidance (learning_courses,learning_guidance,learning_level,learning_subject_area) values (?,?,?,?)]; constraint [learning_ml_guidance_learning_guidance_learning_subject_are_key]
INFO:2024-06-19 23:14:32,338 run_model - SCRIPT STARTED
INFO:2024-06-19 23:14:32,798 post_data - ===> не удалось загрузить рекомендации на портал: 
 could not execute statement [ERROR: duplicate key value violates unique constraint "learning_ml_guidance_learning_guidance_learning_subject_are_key"
  Detail: Key (learning_guidance, learning_subject_area, learning_level)=(career, hr, 1) already exists.] [insert into learning_ml_guidance (learning_courses,learning_guidance,learning_level,learning_subject_area) values (?,?,?,?)]; SQL [insert into learning_ml_guidance (learning_courses,learning_guidance,learning_level,learning_subject_area) values (?,?,?,?)]; constraint [learning_ml_guidance_learning_guidance_learning_subject_are_key]
INFO:2024-06-19 23:14:46,860 run_model - SCRIPT STARTED
WARNING:2024-06-19 23:14:47,132 post_data - ===> не удалось загрузить рекомендации на портал: 
 could not execute statement [ERROR: duplicate key value violates unique constraint "learning_ml_guidance_learning_guidance_learning_subject_are_key"
  Detail: Key (learning_guidance, learning_subject_area, learning_level)=(career, hr, 1) already exists.] [insert into learning_ml_guidance (learning_courses,learning_guidance,learning_level,learning_subject_area) values (?,?,?,?)]; SQL [insert into learning_ml_guidance (learning_courses,learning_guidance,learning_level,learning_subject_area) values (?,?,?,?)]; constraint [learning_ml_guidance_learning_guidance_learning_subject_are_key]
INFO:2024-06-19 23:35:17,598 run_model - SCRIPT STARTED
WARNING:2024-06-19 23:35:18,058 post_data - could not execute statement [ERROR: duplicate key value violates unique constraint "learning_ml_guidance_learning_guidance_learning_subject_are_key"
  Detail: Key (learning_guidance, learning_subject_area, learning_level)=(career, hr, 1) already exists.] [insert into learning_ml_guidance (learning_courses,learning_guidance,learning_level,learning_subject_area) values (?,?,?,?)]; SQL [insert into learning_ml_guidance (learning_courses,learning_guidance,learning_level,learning_subject_area) values (?,?,?,?)]; constraint [learning_ml_guidance_learning_guidance_learning_subject_are_key]
INFO:2024-06-19 23:36:12,149 run_model - SCRIPT STARTED
WARNING:2024-06-19 23:36:12,488 post_data - could not execute statement [ERROR: duplicate key value violates unique constraint "learning_ml_guidance_learning_guidance_learning_subject_are_key"
  Detail: Key (learning_guidance, learning_subject_area, learning_level)=(career, hr, 1) already exists.] [insert into learning_ml_guidance (learning_courses,learning_guidance,learning_level,learning_subject_area) values (?,?,?,?)]; SQL [insert into learning_ml_guidance (learning_courses,learning_guidance,learning_level,learning_subject_area) values (?,?,?,?)]; constraint [learning_ml_guidance_learning_guidance_learning_subject_are_key]
INFO:2024-06-19 23:43:41,446 run_model - SCRIPT STARTED
WARNING:2024-06-19 23:43:41,723 post_data - could not execute statement [ERROR: duplicate key value violates unique constraint "learning_ml_guidance_learning_guidance_learning_subject_are_key"
  Detail: Key (learning_guidance, learning_subject_area, learning_level)=(career, hr, 1) already exists.] [insert into learning_ml_guidance (learning_courses,learning_guidance,learning_level,learning_subject_area) values (?,?,?,?)]; SQL [insert into learning_ml_guidance (learning_courses,learning_guidance,learning_level,learning_subject_area) values (?,?,?,?)]; constraint [learning_ml_guidance_learning_guidance_learning_subject_are_key]
WARNING:2024-06-19 23:43:41,724 post_data - ===> не удалось загрузить рекомендации на портал: 
 could not execute statement [ERROR: duplicate key value violates unique constraint "learning_ml_guidance_learning_guidance_learning_subject_are_key"
  Detail: Key (learning_guidance, learning_subject_area, learning_level)=(career, hr, 1) already exists.] [insert into learning_ml_guidance (learning_courses,learning_guidance,learning_level,learning_subject_area) values (?,?,?,?)]; SQL [insert into learning_ml_guidance (learning_courses,learning_guidance,learning_level,learning_subject_area) values (?,?,?,?)]; constraint [learning_ml_guidance_learning_guidance_learning_subject_are_key]
INFO:2024-06-19 23:43:47,445 run_model - SCRIPT STARTED
WARNING:2024-06-19 23:43:47,714 post_data - could not execute statement [ERROR: duplicate key value violates unique constraint "learning_ml_guidance_learning_guidance_learning_subject_are_key"
  Detail: Key (learning_guidance, learning_subject_area, learning_level)=(career, hr, 1) already exists.] [insert into learning_ml_guidance (learning_courses,learning_guidance,learning_level,learning_subject_area) values (?,?,?,?)]; SQL [insert into learning_ml_guidance (learning_courses,learning_guidance,learning_level,learning_subject_area) values (?,?,?,?)]; constraint [learning_ml_guidance_learning_guidance_learning_subject_are_key]
WARNING:2024-06-19 23:43:47,714 post_data - ===> не удалось загрузить рекомендации на портал: 
 could not execute statement [ERROR: duplicate key value violates unique constraint "learning_ml_guidance_learning_guidance_learning_subject_are_key"
  Detail: Key (learning_guidance, learning_subject_area, learning_level)=(career, hr, 1) already exists.] [insert into learning_ml_guidance (learning_courses,learning_guidance,learning_level,learning_subject_area) values (?,?,?,?)]; SQL [insert into learning_ml_guidance (learning_courses,learning_guidance,learning_level,learning_subject_area) values (?,?,?,?)]; constraint [learning_ml_guidance_learning_guidance_learning_subject_are_key]
